Workbook

Sheet Leesmij
A1: Hypotheek-toetsmodel 2026
A2: Onafhankelijk Excel-model van de leencapaciteitstoets (Nibud-woonquote, toetsrente, studieschuld, meenemen van bestaande leningdelen) om de hypotheekcalculator mee te controleren.
A4: Doel
A5: Dit werkboek rekent dezelfde toets als de app, maar volledig met cel-formules. U voert een dossier in (Invoer, kolom C of M), leest de uitkomst in Samenvatting en vergelijkt desgewenst met de app (Controle).
A7: Werkbladen
A8: Samenvatting: opbouw van de leencapaciteit en de uitkomst voor het gekozen scenario (cel C4).
A9: Invoer: alle invoer per scenario. Gele cellen met blauwe tekst zijn invoer. Kolom C = uw dossier, D t/m L = testscenario's, M = vrij testscenario.
A10: Berekening: stap voor stap, alles formules. Groene vakken zijn sleutelresultaten.
A11: Solver: bepaalt het hoogste bedrag nieuw geld bij meenemen, waarbij de woonquote meebeweegt met de gewogen toetsrente.
A12: Tabellen: parameters en de woonquote-tabellen. Oranje kolommen zijn GESCHAT (zie hieronder) en kunnen worden overschreven.
A13: Controle: Excel-uitkomst naast de uitkomst van de app-engine voor de testscenario's, met verschil en status.
A14: Bronnen: wat is geverifieerd, wat niet, en hoe zeker.
... A32: Indicatief; geen bindend advies. Peildatum scenario's: 8 oktober 2026.

Sheet Samenvatting
A1: Samenvatting: wat kunt u lenen?
A2: Kies een scenario (1 t/m 11). Alle cijfers komen uit de berekening; scenario 1 is uw eigen dossier.
A4: Gekozen scenario | C4: 1
A6: Scenario
A7: Naam | C7: =INDEX(Invoer!$C$6:$M$6,$C$4) -> Mijn dossier
A8: Type | C8: =IF(INDEX(Berekening!$C$6:$M$6,$C$4)=1,"Doorstromer","Starter") -> Doorstromer
A9: Opbouw van de leencapaciteit
A10: Leencapaciteit op inkomen (woonquote × inkomen, gekapitaliseerd) | C10: =INDEX(Berekening!$C$83:$M$83,$C$4) -> 1056874.5
A11: − Schulden en tweede woning | C11: =-MIN(INDEX(Berekening!$C$18:$M$18,$C$4)*INDEX(Berekening!$C$11:$M$11,$C$4),INDEX(Berekening!$C$83:$M$83,$C$4)) -> -37286.07
A12: − Studieschuld | C12: =-MIN(INDEX(Berekening!$C$75:$M$75,$C$4),INDEX(Berekening!$C$84:$M$84,$C$4)) -> -80110.119
A13: ± Correctie (ondergrens € 0; normaal 0) | C13: =C17-(C10+C11+C12+C14+C15+C16) -> 0
A14: ± AOW-toets (pensioeninkomen bindend) | C14: =INDEX(Berekening!$C$100:$M$100,$C$4)-INDEX(Berekening!$C$85:$M$85,$C$4) -> 0
A15: + Energielabelbonus | C15: =INDEX(Berekening!$C$87:$M$87,$C$4) -> 10000
A16: + Alleenstaandenbedrag | C16: =INDEX(Berekening!$C$86:$M$86,$C$4) -> 0
A17: Maximale hypotheek o.b.v. inkomen (alles tegen de toetsrente) | C17: =INDEX(Berekening!$C$101:$M$101,$C$4) -> 949478.28
A18: − Toetslast meegenomen leningdelen (omgerekend in euro's) | C18: =-IF(INDEX(Berekening!$C$47:$M$47,$C$4)=1,INDEX(Berekening!$C$44:$M$44,$C$4)*INDEX(Berekening!$C$11:$M$11,$C$4),0) -> -555976.31
A19: ± Woonquote bij gewogen toetsrente en overig (restpost) | C19: =C20-(C17+C18) -> -65149.796
A20: Ruimte voor nieuw geld (inkomen) | C20: =INDEX(Berekening!$C$105:$M$105,$C$4) -> 328352.17
A21: − Plafond geldverstrekker (alleen als dat lager is) | C21: =C22-C20 -> 0
A22: Maximaal nieuw te lenen | C22: =INDEX(Berekening!$C$118:$M$118,$C$4) -> 328352.17
A23: Uitkomst
A24: Maximale totale hypotheek | C24: =INDEX(Berekening!$C$117:$M$117,$C$4) -> 952102.08
A25: waarvan meegenomen (al geleend) | C25: =INDEX(Berekening!$C$43:$M$43,$C$4) -> 623749.91
A26: Nieuw geld nodig voor de aankoopprijs | C26: =INDEX(Berekening!$C$119:$M$119,$C$4) -> 323980
A27: Ruimte (+) of tekort (−) | C27: =INDEX(Berekening!$C$120:$M$120,$C$4) -> 4372.1704
A28: Haalbaar? | C28: =IF(INDEX(Berekening!$C$122:$M$122,$C$4)=1,"Ja, deze woning past","Nee, deze woning past nog niet") -> Ja, deze woning past
A29: Kerngetallen
A30: Totaal toetsinkomen | C30: =INDEX(Berekening!$C$9:$M$9,$C$4) -> 225000
A31: Toetsrente nieuw geld | C31: =INDEX(Berekening!$C$10:$M$10,$C$4) -> 0.0469
A32: Woonquote bij de toetsrente van het nieuwe geld | C32: =INDEX(Berekening!$C$81:$M$81,$C$4) -> 0.292
A33: Gewogen toetsrente nieuwe hypotheek bij het maximum | C33: =INDEX(Berekening!$C$107:$M$107,$C$4) -> 0.036487604
A34: Opslagfactor studieschuld | C34: =INDEX(Berekening!$C$71:$M$71,$C$4) -> 1.25
A35: Kosten koper | C35: =INDEX(Berekening!$C$56:$M$56,$C$4) -> 32230
A36: Overgebleven budget na woning en kosten koper | C36: =INDEX(Berekening!$C$123:$M$123,$C$4) -> 4372.1704

Sheet Invoer
A1: Invoer
A2: Vul alleen de gele cellen met blauwe tekst in. Kolom C is uw eigen dossier; D t/m L zijn testscenario's met bekende app-uitkomst; M is een vrij testscenario.
A4: Scenario | B4: Eenheid | C4: 1 | D4: 2 | E4: 3 | F4: 4 | G4: 5 | H4: 6 | I4: 7 | J4: 8 | K4: 9 | L4: 10 | M4: 11
A5: Algemeen
A6: Naam scenario | C6: Mijn dossier | D6: Plafond € 1,5 mln, 30 jaar toetsloptijd | E6: Deel 2 slechts 10 jaar rentevast | F6: Nieuwe hypotheek 5 jaar rentevast | G6: Starter, 1 aanvrager € 60k | H6: Starter, 2 aanvragers, studieschuld | I6: Doorstromer, hypotheek niet meenemen | J6: AOW-toets bindend (leeftijd 60) | K6: 3 delen, 2e woning 5 jaar vast, schulden | L6: Hoge schuld: ondergrens € 0 | M6: Eigen test
A7: Doorstromer (bestaande woning)? | B7: Ja/Nee | C7: Ja | D7: Ja | E7: Ja | F7: Ja | G7: Nee | H7: Nee | I7: Ja | J7: Ja | K7: Ja | L7: Ja | M7: Ja
A8: Twee aanvragers? | B8: Ja/Nee | C8: Ja | D8: Ja | E8: Ja | F8: Ja | G8: Nee | H8: Ja | I8: Ja | J8: Ja | K8: Ja | L8: Ja | M8: Ja
A9: Inkomen en leeftijd
A10: Toetsinkomen aanvrager 1 | B10: € per jaar | C10: 118000 | D10: 118000 | E10: 118000 | F10: 118000 | G10: 60000 | H10: 80000 | I10: 118000 | J10: 118000 | K10: 118000 | L10: 118000 | M10: 118000
A11: Toetsinkomen aanvrager 2 | B11: € per jaar | C11: 107000 | D11: 107000 | E11: 107000 | F11: 107000 | G11: 0 | H11: 70000 | I11: 107000 | J11: 107000 | K11: 107000 | L11: 107000 | M11: 107000
A12: Leeftijd aanvrager 1 | B12: jaar | C12: 36 | D12: 36 | E12: 36 | F12: 36 | G12: 30 | H12: 31 | I12: 36 | J12: 60 | K12: 36 | L12: 36 | M12: 36
A13: Leeftijd aanvrager 2 | B13: jaar | C13: 36 | D13: 36 | E13: 36 | F13: 36 | G13: 36 | H13: 29 | I13: 36 | J13: 36 | K13: 36 | L13: 36 | M13: 36
A14: Verwacht pensioeninkomen aanvrager 1 (bij ≥ 57 jaar) | B14: € per jaar | C14: 0 | D14: 0 | E14: 0 | F14: 0 | G14: 0 | H14: 0 | I14: 0 | J14: 40000 | K14: 0 | L14: 0 | M14: 0
A15: Verwacht pensioeninkomen aanvrager 2 (bij ≥ 57 jaar) | B15: € per jaar | C15: 0 | D15: 0 | E15: 0 | F15: 0 | G15: 0 | H15: 0 | I15: 0 | J15: 0 | K15: 0 | L15: 0 | M15: 0
A16: Energielabel woning | B16: label | C16: A | D16: A | E16: A | F16: A | G16: C | H16: B | I16: A | J16: A | K16: G | L16: A | M16: A
A17: Nieuwe hypotheek
A18: Rente nieuwe hypotheek | B18: % per jaar | C18: 0.0469 | D18: 0.0469 | E18: 0.0469 | F18: 0.0469 | G18: 0.0469 | H18: 0.0469 | I18: 0.0469 | J18: 0.0469 | K18: 0.0469 | L18: 0.0469 | M18: 0.0469
A19: Rentevaste periode nieuwe hypotheek | B19: jaar | C19: 10 | D19: 10 | E19: 10 | F19: 5 | G19: 10 | H19: 10 | I19: 10 | J19: 10 | K19: 10 | L19: 10 | M19: 10
A20: Aankoopprijs beoogde woning | B20: € | C20: 1330000 | D20: 1330000 | E20: 1330000 | F20: 1330000 | G20: 400000 | H20: 650000 | I20: 1330000 | J20: 1330000 | K20: 1100000 | L20: 1330000 | M20: 1330000
A21: Plafond totale hypotheek bij geldverstrekker | B21: € | C21: 1000000 | D21: 1500000 | E21: 1000000 | F21: 1000000 | G21: 1000000 | H21: 1000000 | I21: 1000000 | J21: 1000000 | K21: 1000000 | L21: 1000000 | M21: 1000000
A22: Schulden en lasten
A23: Overige schulden aanvrager 1 (kredietbedrag) | B23: € | C23: 0 | D23: 0 | E23: 0 | F23: 0 | G23: 0 | H23: 0 | I23: 0 | J23: 0 | K23: 15000 | L23: 3000000 | M23: 0
A24: Overige schulden aanvrager 2 (kredietbedrag) | B24: € | C24: 0 | D24: 0 | E24: 0 | F24: 0 | G24: 0 | H24: 0 | I24: 0 | J24: 0 | K24: 8000 | L24: 0 | M24: 0
A25: Maandelijkse aflossing familielening | B25: € per maand | C25: 0 | D25: 0 | E25: 0 | F25: 0 | G25: 0 | H25: 0 | I25: 0 | J25: 0 | K25: 250 | L25: 0 | M25: 0
A26: Studieschuld: totaal maandbedrag DUO (alle leningen) | B26: € per maand | C26: 332 | D26: 332 | E26: 332 | F26: 332 | G26: 0 | H26: 120 | I26: 332 | J26: 332 | K26: 332 | L26: 332 | M26: 332
A27: Studieschuld: debetrente voor opslagfactor | B27: keuze | C27: Gewogen toetsrente | D27: Gewogen toetsrente | E27: Gewogen toetsrente | F27: Gewogen toetsrente | G27: Gewogen toetsrente | H27: Gewogen toetsrente | I27: Gewogen toetsrente | J27: Gewogen toetsrente | K27: Contractrente | L27: Gewogen toetsrente | M27: Gewogen toetsrente
A28: Studieschuld: kapitaliseren tegen | B28: keuze | C28: Marginaal | D28: Marginaal | E28: Marginaal | F28: Marginaal | G28: Marginaal | H28: Gewogen | I28: Marginaal | J28: Marginaal | K28: Marginaal | L28: Marginaal | M28: Marginaal
A29: Tweede woning (aanhouden)
A30: Tweede woning met hypotheek aanhouden? | B30: Ja/Nee | C30: Ja | D30: Ja | E30: Ja | F30: Ja | G30: Nee | H30: Nee | I30: Ja | J30: Nee | K30: Ja | L30: Nee | M30: Ja
A31: Hypotheekschuld tweede woning | B31: € | C31: 42000 | D31: 42000 | E31: 42000 | F31: 42000 | G31: 42000 | H31: 42000 | I31: 42000 | J31: 42000 | K31: 42000 | L31: 42000 | M31: 42000
A32: Rente tweede woning | B32: % per jaar | C32: 0.01 | D32: 0.01 | E32: 0.01 | F32: 0.01 | G32: 0.01 | H32: 0.01 | I32: 0.01 | J32: 0.01 | K32: 0.01 | L32: 0.01 | M32: 0.01
A33: Aflosvorm tweede woning | B33: keuze | C33: Annuïteit | D33: Annuïteit | E33: Annuïteit | F33: Annuïteit | G33: Annuïteit | H33: Annuïteit | I33: Annuïteit | J33: Annuïteit | K33: Aflossingsvrij | L33: Annuïteit | M33: Annuïteit
A34: Resterende looptijd tweede woning | B34: jaar | C34: 20 | D34: 20 | E34: 20 | F34: 20 | G34: 20 | H34: 20 | I34: 20 | J34: 20 | K34: 20 | L34: 20 | M34: 20
A35: Resterende rentevaste periode tweede woning | B35: jaar | C35: 10 | D35: 10 | E35: 10 | F35: 10 | G35: 10 | H35: 10 | I35: 10 | J35: 10 | K35: 5 | L35: 10 | M35: 10
A36: Bestaande hypotheek (alleen doorstromer)
A37: Hypotheek meenemen naar de nieuwe woning? | B37: Ja/Nee | C37: Ja | D37: Ja | E37: Ja | F37: Ja | G37: Ja | H37: Ja | I37: Nee | J37: Ja | K37: Ja | L37: Ja | M37: Ja
A38: Looptijd voor toetslast meegenomen delen | B38: keuze | C38: Resterend | D38: 30 jaar | E38: Resterend | F38: Resterend | G38: Resterend | H38: Resterend | I38: Resterend | J38: Resterend | K38: Resterend | L38: Resterend | M38: Resterend
A39: Ingangsdatum hypotheek | B39: datum | C39: 44211 | D39: 44211 | E39: 44211 | F39: 44211 | G39: 44211 | H39: 44211 | I39: 44211 | J39: 44211 | K39: 44211 | L39: 44211 | M39: 44211
A40: Peildatum (restsaldi) | B40: datum | C40: 46303 | D40: 46303 | E40: 46303 | F40: 46303 | G40: 46303 | H40: 46303 | I40: 46303 | J40: 46303 | K40: 46303 | L40: 46303 | M40: 46303
A41: Leningdeel 1
...

Sheet Berekening
A1: Berekening
A2: Alle cellen zijn formules. Opbouw per scenariokolom; groen = sleutelresultaat. Rente-invoer staat als fractie (4,00% = 0,04).
A4: Stap | B4: Eenheid | C4: =Invoer!C4 -> 1 | D4: =Invoer!D4 -> 2 | E4: =Invoer!E4 -> 3 | F4: =Invoer!F4 -> 4 | G4: =Invoer!G4 -> 5 | H4: =Invoer!H4 -> 6 | I4: =Invoer!I4 -> 7 | J4: =Invoer!J4 -> 8 | ... M4: =Invoer!M4 -> 11
A5: 1. Uitgangspunten
A6: Doorstromer (1 = ja) | C6: =IF(Invoer!C7="Ja",1,0) -> 1 | D6: =IF(Invoer!D7="Ja",1,0) -> 1 | E6: =IF(Invoer!E7="Ja",1,0) -> 1 | F6: =IF(Invoer!F7="Ja",1,0) -> 1 | G6: =IF(Invoer!G7="Ja",1,0) -> 0 | H6: =IF(Invoer!H7="Ja",1,0) -> 0 | I6: =IF(Invoer!I7="Ja",1,0) -> 1 | J6: =IF(Invoer!J7="Ja",1,0) -> 1 | ... M6: =IF(Invoer!M7="Ja",1,0) -> 1
A7: Twee aanvragers (1 = ja) | C7: =IF(Invoer!C8="Ja",1,0) -> 1 | D7: =IF(Invoer!D8="Ja",1,0) -> 1 | E7: =IF(Invoer!E8="Ja",1,0) -> 1 | F7: =IF(Invoer!F8="Ja",1,0) -> 1 | G7: =IF(Invoer!G8="Ja",1,0) -> 0 | H7: =IF(Invoer!H8="Ja",1,0) -> 1 | I7: =IF(Invoer!I8="Ja",1,0) -> 1 | J7: =IF(Invoer!J8="Ja",1,0) -> 1 | ... M7: =IF(Invoer!M8="Ja",1,0) -> 1
A8: Hypotheek wordt meegenomen (1 = ja) | C8: =C6*IF(Invoer!C37="Ja",1,0) -> 1 | D8: =D6*IF(Invoer!D37="Ja",1,0) -> 1 | E8: =E6*IF(Invoer!E37="Ja",1,0) -> 1 | F8: =F6*IF(Invoer!F37="Ja",1,0) -> 1 | G8: =G6*IF(Invoer!G37="Ja",1,0) -> 0 | H8: =H6*IF(Invoer!H37="Ja",1,0) -> 0 | I8: =I6*IF(Invoer!I37="Ja",1,0) -> 0 | J8: =J6*IF(Invoer!J37="Ja",1,0) -> 1 | ... M8: =M6*IF(Invoer!M37="Ja",1,0) -> 1
A9: Totaal toetsinkomen | B9: € | C9: =Invoer!C10+C7*Invoer!C11 -> 225000 | D9: =Invoer!D10+D7*Invoer!D11 -> 225000 | E9: =Invoer!E10+E7*Invoer!E11 -> 225000 | F9: =Invoer!F10+F7*Invoer!F11 -> 225000 | G9: =Invoer!G10+G7*Invoer!G11 -> 60000 | H9: =Invoer!H10+H7*Invoer!H11 -> 150000 | I9: =Invoer!I10+I7*Invoer!I11 -> 225000 | J9: =Invoer!J10+J7*Invoer!J11 -> 225000 | ... M9: =Invoer!M10+M7*Invoer!M11 -> 225000
A10: Toetsrente nieuwe hypotheek | B10: % | C10: =IF(AND(Invoer!C19<10,AFM_Toetsrente>Invoer!C18),AFM_Toetsrente,Invoer!C18) -> 0.0469 | D10: =IF(AND(Invoer!D19<10,AFM_Toetsrente>Invoer!D18),AFM_Toetsrente,Invoer!D18) -> 0.0469 | E10: =IF(AND(Invoer!E19<10,AFM_Toetsrente>Invoer!E18),AFM_Toetsrente,Invoer!E18) -> 0.0469 | F10: =IF(AND(Invoer!F19<10,AFM_Toetsrente>Invoer!F18),AFM_Toetsrente,Invoer!F18) -> 0.05 | G10: =IF(AND(Invoer!G19<10,AFM_Toetsrente>Invoer!G18),AFM_Toetsrente,Invoer!G18) -> 0.0469 | H10: =IF(AND(Invoer!H19<10,AFM_Toetsrente>Invoer!H18),AFM_Toetsrente,Invoer!H18) -> 0.0469 | I10: =IF(AND(Invoer!I19<10,AFM_Toetsrente>Invoer!I18),AFM_Toetsrente,Invoer!I18) -> 0.0469 | J10: =IF(AND(Invoer!J19<10,AFM_Toetsrente>Invoer!J18),AFM_Toetsrente,Invoer!J18) -> 0.0469 | ... M10: =IF(AND(Invoer!M19<10,AFM_Toetsrente>Invoer!M18),AFM_Toetsrente,Invoer!M18) -> 0.0469
A11: Kapitalisatiefactor (360 mnd) bij toetsrente | C11: =IF(C10=0,360,(1-(1+C10/12)^(-360))/(C10/12)) -> 193.03643 | D11: =IF(D10=0,360,(1-(1+D10/12)^(-360))/(D10/12)) -> 193.03643 | E11: =IF(E10=0,360,(1-(1+E10/12)^(-360))/(E10/12)) -> 193.03643 | F11: =IF(F10=0,360,(1-(1+F10/12)^(-360))/(F10/12)) -> 186.28162 | G11: =IF(G10=0,360,(1-(1+G10/12)^(-360))/(G10/12)) -> 193.03643 | H11: =IF(H10=0,360,(1-(1+H10/12)^(-360))/(H10/12)) -> 193.03643 | I11: =IF(I10=0,360,(1-(1+I10/12)^(-360))/(I10/12)) -> 193.03643 | J11: =IF(J10=0,360,(1-(1+J10/12)^(-360))/(J10/12)) -> 193.03643 | ... M11: =IF(M10=0,360,(1-(1+M10/12)^(-360))/(M10/12)) -> 193.03643
A12: 2. Schulden en lasten
A13: Overige schulden: maandlast (2%) | B13: € p/m | C13: =(Invoer!C23+C7*Invoer!C24)*Weging_overig -> 0 | D13: =(Invoer!D23+D7*Invoer!D24)*Weging_overig -> 0 | E13: =(Invoer!E23+E7*Invoer!E24)*Weging_overig -> 0 | F13: =(Invoer!F23+F7*Invoer!F24)*Weging_overig -> 0 | G13: =(Invoer!G23+G7*Invoer!G24)*Weging_overig -> 0 | H13: =(Invoer!H23+H7*Invoer!H24)*Weging_overig -> 0 | I13: =(Invoer!I23+I7*Invoer!I24)*Weging_overig -> 0 | J13: =(Invoer!J23+J7*Invoer!J24)*Weging_overig -> 0 | ... M13: =(Invoer!M23+M7*Invoer!M24)*Weging_overig -> 0
A14: Tweede woning aangehouden (1 = ja) | C14: =IF(Invoer!C30="Ja",1,0) -> 1 | D14: =IF(Invoer!D30="Ja",1,0) -> 1 | E14: =IF(Invoer!E30="Ja",1,0) -> 1 | F14: =IF(Invoer!F30="Ja",1,0) -> 1 | G14: =IF(Invoer!G30="Ja",1,0) -> 0 | H14: =IF(Invoer!H30="Ja",1,0) -> 0 | I14: =IF(Invoer!I30="Ja",1,0) -> 1 | J14: =IF(Invoer!J30="Ja",1,0) -> 0 | ... M14: =IF(Invoer!M30="Ja",1,0) -> 1
A15: Tweede woning: toetsrente | B15: % | C15: =C14*IF(AND(Invoer!C35<10,AFM_Toetsrente>Invoer!C32),AFM_Toetsrente,Invoer!C32) -> 0.01 | D15: =D14*IF(AND(Invoer!D35<10,AFM_Toetsrente>Invoer!D32),AFM_Toetsrente,Invoer!D32) -> 0.01 | E15: =E14*IF(AND(Invoer!E35<10,AFM_Toetsrente>Invoer!E32),AFM_Toetsrente,Invoer!E32) -> 0.01 | F15: =F14*IF(AND(Invoer!F35<10,AFM_Toetsrente>Invoer!F32),AFM_Toetsrente,Invoer!F32) -> 0.01 | G15: =G14*IF(AND(Invoer!G35<10,AFM_Toetsrente>Invoer!G32),AFM_Toetsrente,Invoer!G32) -> 0 | H15: =H14*IF(AND(Invoer!H35<10,AFM_Toetsrente>Invoer!H32),AFM_Toetsrente,Invoer!H32) -> 0 | I15: =I14*IF(AND(Invoer!I35<10,AFM_Toetsrente>Invoer!I32),AFM_Toetsrente,Invoer!I32) -> 0.01 | J15: =J14*IF(AND(Invoer!J35<10,AFM_Toetsrente>Invoer!J32),AFM_Toetsrente,Invoer!J32) -> 0 | ... M15: =M14*IF(AND(Invoer!M35<10,AFM_Toetsrente>Invoer!M32),AFM_Toetsrente,Invoer!M32) -> 0.01
A16: Tweede woning: toetslooptijd | B16: maanden | C16: =IF(Invoer!C33="Aflossingsvrij",360,MIN(360,MAX(1,ROUND(Invoer!C34*12,0)))) -> 240 | D16: =IF(Invoer!D33="Aflossingsvrij",360,MIN(360,MAX(1,ROUND(Invoer!D34*12,0)))) -> 240 | E16: =IF(Invoer!E33="Aflossingsvrij",360,MIN(360,MAX(1,ROUND(Invoer!E34*12,0)))) -> 240 | F16: =IF(Invoer!F33="Aflossingsvrij",360,MIN(360,MAX(1,ROUND(Invoer!F34*12,0)))) -> 240 | G16: =IF(Invoer!G33="Aflossingsvrij",360,MIN(360,MAX(1,ROUND(Invoer!G34*12,0)))) -> 240 | H16: =IF(Invoer!H33="Aflossingsvrij",360,MIN(360,MAX(1,ROUND(Invoer!H34*12,0)))) -> 240 | I16: =IF(Invoer!I33="Aflossingsvrij",360,MIN(360,MAX(1,ROUND(Invoer!I34*12,0)))) -> 240 | J16: =IF(Invoer!J33="Aflossingsvrij",360,MIN(360,MAX(1,ROUND(Invoer!J34*12,0)))) -> 240 | ... M16: =IF(Invoer!M33="Aflossingsvrij",360,MIN(360,MAX(1,ROUND(Invoer!M34*12,0)))) -> 240
A17: Tweede woning: toetslast | B17: € p/m | C17: =C14*IF(Invoer!C31<=0,0,IF(C15=0,Invoer!C31/C16,Invoer!C31*(C15/12)/(1-(1+C15/12)^(-C16)))) -> 193.15561 | D17: =D14*IF(Invoer!D31<=0,0,IF(D15=0,Invoer!D31/D16,Invoer!D31*(D15/12)/(1-(1+D15/12)^(-D16)))) -> 193.15561 | E17: =E14*IF(Invoer!E31<=0,0,IF(E15=0,Invoer!E31/E16,Invoer!E31*(E15/12)/(1-(1+E15/12)^(-E16)))) -> 193.15561 | F17: =F14*IF(Invoer!F31<=0,0,IF(F15=0,Invoer!F31/F16,Invoer!F31*(F15/12)/(1-(1+F15/12)^(-F16)))) -> 193.15561 | G17: =G14*IF(Invoer!G31<=0,0,IF(G15=0,Invoer!G31/G16,Invoer!G31*(G15/12)/(1-(1+G15/12)^(-G16)))) -> 0 | H17: =H14*IF(Invoer!H31<=0,0,IF(H15=0,Invoer!H31/H16,Invoer!H31*(H15/12)/(1-(1+H15/12)^(-H16)))) -> 0 | I17: =I14*IF(Invoer!I31<=0,0,IF(I15=0,Invoer!I31/I16,Invoer!I31*(I15/12)/(1-(1+I15/12)^(-I16)))) -> 193.15561 | J17: =J14*IF(Invoer!J31<=0,0,IF(J15=0,Invoer!J31/J16,Invoer!J31*(J15/12)/(1-(1+J15/12)^(-J16)))) -> 0 | ... M17: =M14*IF(Invoer!M31<=0,0,IF(M15=0,Invoer!M31/M16,Invoer!M31*(M15/12)/(1-(1+M15/12)^(-M16)))) -> 193.15561
A18: Totale maandlast schulden (excl. studieschuld) | B18: € p/m | C18: =C13+C17+Invoer!C25 -> 193.15561 | D18: =D13+D17+Invoer!D25 -> 193.15561 | E18: =E13+E17+Invoer!E25 -> 193.15561 | F18: =F13+F17+Invoer!F25 -> 193.15561 | G18: =G13+G17+Invoer!G25 -> 0 | H18: =H13+H17+Invoer!H25 -> 0 | I18: =I13+I17+Invoer!I25 -> 193.15561 | J18: =J13+J17+Invoer!J25 -> 0 | ... M18: =M13+M17+Invoer!M25 -> 193.15561
A19: 3. Bestaande hypotheek: toets per leningdeel
A20: Verstreken maanden sinds ingangsdatum | B20: maanden | C20: =IFERROR(DATEDIF(Invoer!C39,Invoer!C40,"m"),0) -> 68 | D20: =IFERROR(DATEDIF(Invoer!D39,Invoer!D40,"m"),0) -> 68 | E20: =IFERROR(DATEDIF(Invoer!E39,Invoer!E40,"m"),0) -> 68 | F20: =IFERROR(DATEDIF(Invoer!F39,Invoer!F40,"m"),0) -> 68 | G20: =IFERROR(DATEDIF(Invoer!G39,Invoer!G40,"m"),0) -> 68 | H20: =IFERROR(DATEDIF(Invoer!H39,Invoer!H40,"m"),0) -> 68 | I20: =IFERROR(DATEDIF(Invoer!I39,Invoer!I40,"m"),0) -> 68 | J20: =IFERROR(DATEDIF(Invoer!J39,Invoer!J40,"m"),0) -> 68 | ... M20: =IFERROR(DATEDIF(Invoer!M39,Invoer!M40,"m"),0) -> 68
A21: Resterende looptijd (360 min verstreken) | B21: maanden | C21: =MAX(1,360-C20) -> 292 | D21: =MAX(1,360-D20) -> 292 | E21: =MAX(1,360-E20) -> 292 | F21: =MAX(1,360-F20) -> 292 | G21: =MAX(1,360-G20) -> 292 | H21: =MAX(1,360-H20) -> 292 | I21: =MAX(1,360-I20) -> 292 | J21: =MAX(1,360-J20) -> 292 | ... M21: =MAX(1,360-M20) -> 292
A22: Deel 1: restsaldo | B22: € | C22: =Invoer!C43 -> 269480.64 | D22: =Invoer!D43 -> 269480.64 | E22: =Invoer!E43 -> 269480.64 | F22: =Invoer!F43 -> 269480.64 | G22: =Invoer!G43 -> 269480.64 | H22: =Invoer!H43 -> 269480.64 | I22: =Invoer!I43 -> 269480.64 | J22: =Invoer!J43 -> 269480.64 | ... M22: =Invoer!M43 -> 269480.64
A23: Deel 1: resterende rentevaste periode | B23: maanden | C23: =MAX(0,Invoer!C45*12-C20) -> 52 | D23: =MAX(0,Invoer!D45*12-D20) -> 52 | E23: =MAX(0,Invoer!E45*12-E20) -> 52 | F23: =MAX(0,Invoer!F45*12-F20) -> 52 | G23: =MAX(0,Invoer!G45*12-G20) -> 52 | H23: =MAX(0,Invoer!H45*12-H20) -> 52 | I23: =MAX(0,Invoer!I45*12-I20) -> 52 | J23: =MAX(0,Invoer!J45*12-J20) -> 52 | ... M23: =MAX(0,Invoer!M45*12-M20) -> 52
A24: Deel 1: toetsrente | B24: % | C24: =IF(C22>0,IF(C23<120,MAX(AFM_Toetsrente,Invoer!C44),Invoer!C44),0) -> 0.05 | D24: =IF(D22>0,IF(D23<120,MAX(AFM_Toetsrente,Invoer!D44),Invoer!D44),0) -> 0.05 | E24: =IF(E22>0,IF(E23<120,MAX(AFM_Toetsrente,Invoer!E44),Invoer!E44),0) -> 0.05 | F24: =IF(F22>0,IF(F23<120,MAX(AFM_Toetsrente,Invoer!F44),Invoer!F44),0) -> 0.05 | G24: =IF(G22>0,IF(G23<120,MAX(AFM_Toetsrente,Invoer!G44),Invoer!G44),0) -> 0.05 | H24: =IF(H22>0,IF(H23<120,MAX(AFM_Toetsrente,Invoer!H44),Invoer!H44),0) -> 0.05 | I24: =IF(I22>0,IF(I23<120,MAX(AFM_Toetsrente,Invoer!I44),Invoer!I44),0) -> 0.05 | J24: =IF(J22>0,IF(J23<120,MAX(AFM_Toetsrente,Invoer!J44),Invoer!J44),0) -> 0.05 | ... M24: =IF(M22>0,IF(M23<120,MAX(AFM_Toetsrente,Invoer!M44),Invoer!M44),0) -> 0.05
A25: Deel 1: toetslooptijd | B25: maanden | C25: =IF(OR(Invoer!C42="Aflossingsvrij",Invoer!C38="30 jaar"),360,C21) -> 292 | D25: =IF(OR(Invoer!D42="Aflossingsvrij",Invoer!D38="30 jaar"),360,D21) -> 360 | E25: =IF(OR(Invoer!E42="Aflossingsvrij",Invoer!E38="30 jaar"),360,E21) -> 292 | F25: =IF(OR(Invoer!F42="Aflossingsvrij",Invoer!F38="30 jaar"),360,F21) -> 292 | G25: =IF(OR(Invoer!G42="Aflossingsvrij",Invoer!G38="30 jaar"),360,G21) -> 292 | H25: =IF(OR(Invoer!H42="Aflossingsvrij",Invoer!H38="30 jaar"),360,H21) -> 292 | I25: =IF(OR(Invoer!I42="Aflossingsvrij",Invoer!I38="30 jaar"),360,I21) -> 292 | J25: =IF(OR(Invoer!J42="Aflossingsvrij",Invoer!J38="30 jaar"),360,J21) -> 292 | ... M25: =IF(OR(Invoer!M42="Aflossingsvrij",Invoer!M38="30 jaar"),360,M21) -> 292
A26: Deel 1: toetslast (annuïteit) | B26: € p/m | C26: =IF(C22<=0,0,IF(C24=0,C22/C25,C22*(C24/12)/(1-(1+C24/12)^(-C25)))) -> 1597.1281 | D26: =IF(D22<=0,0,IF(D24=0,D22/D25,D22*(D24/12)/(1-(1+D24/12)^(-D25)))) -> 1446.6303 | E26: =IF(E22<=0,0,IF(E24=0,E22/E25,E22*(E24/12)/(1-(1+E24/12)^(-E25)))) -> 1597.1281 | F26: =IF(F22<=0,0,IF(F24=0,F22/F25,F22*(F24/12)/(1-(1+F24/12)^(-F25)))) -> 1597.1281 | G26: =IF(G22<=0,0,IF(G24=0,G22/G25,G22*(G24/12)/(1-(1+G24/12)^(-G25)))) -> 1597.1281 | H26: =IF(H22<=0,0,IF(H24=0,H22/H25,H22*(H24/12)/(1-(1+H24/12)^(-H25)))) -> 1597.1281 | I26: =IF(I22<=0,0,IF(I24=0,I22/I25,I22*(I24/12)/(1-(1+I24/12)^(-I25)))) -> 1597.1281 | J26: =IF(J22<=0,0,IF(J24=0,J22/J25,J22*(J24/12)/(1-(1+J24/12)^(-J25)))) -> 1597.1281 | ... M26: =IF(M22<=0,0,IF(M24=0,M22/M25,M22*(M24/12)/(1-(1+M24/12)^(-M25)))) -> 1597.1281
A27: Deel 2: restsaldo | B27: € | C27: =Invoer!C48 -> 354269.27 | D27: =Invoer!D48 -> 354269.27 | E27: =Invoer!E48 -> 354269.27 | F27: =Invoer!F48 -> 354269.27 | G27: =Invoer!G48 -> 354269.27 | H27: =Invoer!H48 -> 354269.27 | I27: =Invoer!I48 -> 354269.27 | J27: =Invoer!J48 -> 354269.27 | ... M27: =Invoer!M48 -> 354269.27
A28: Deel 2: resterende rentevaste periode | B28: maanden | C28: =MAX(0,Invoer!C50*12-C20) -> 172 | D28: =MAX(0,Invoer!D50*12-D20) -> 172 | E28: =MAX(0,Invoer!E50*12-E20) -> 52 | F28: =MAX(0,Invoer!F50*12-F20) -> 172 | G28: =MAX(0,Invoer!G50*12-G20) -> 172 | H28: =MAX(0,Invoer!H50*12-H20) -> 172 | I28: =MAX(0,Invoer!I50*12-I20) -> 172 | J28: =MAX(0,Invoer!J50*12-J20) -> 172 | ... M28: =MAX(0,Invoer!M50*12-M20) -> 172
A29: Deel 2: toetsrente | B29: % | C29: =IF(C27>0,IF(C28<120,MAX(AFM_Toetsrente,Invoer!C49),Invoer!C49),0) -> 0.0185 | D29: =IF(D27>0,IF(D28<120,MAX(AFM_Toetsrente,Invoer!D49),Invoer!D49),0) -> 0.0185 | E29: =IF(E27>0,IF(E28<120,MAX(AFM_Toetsrente,Invoer!E49),Invoer!E49),0) -> 0.05 | F29: =IF(F27>0,IF(F28<120,MAX(AFM_Toetsrente,Invoer!F49),Invoer!F49),0) -> 0.0185 | G29: =IF(G27>0,IF(G28<120,MAX(AFM_Toetsrente,Invoer!G49),Invoer!G49),0) -> 0.0185 | H29: =IF(H27>0,IF(H28<120,MAX(AFM_Toetsrente,Invoer!H49),Invoer!H49),0) -> 0.0185 | I29: =IF(I27>0,IF(I28<120,MAX(AFM_Toetsrente,Invoer!I49),Invoer!I49),0) -> 0.0185 | J29: =IF(J27>0,IF(J28<120,MAX(AFM_Toetsrente,Invoer!J49),Invoer!J49),0) -> 0.0185 | ... M29: =IF(M27>0,IF(M28<120,MAX(AFM_Toetsrente,Invoer!M49),Invoer!M49),0) -> 0.0185
A30: Deel 2: toetslooptijd | B30: maanden | C30: =IF(OR(Invoer!C47="Aflossingsvrij",Invoer!C38="30 jaar"),360,C21) -> 360 | D30: =IF(OR(Invoer!D47="Aflossingsvrij",Invoer!D38="30 jaar"),360,D21) -> 360 | E30: =IF(OR(Invoer!E47="Aflossingsvrij",Invoer!E38="30 jaar"),360,E21) -> 360 | F30: =IF(OR(Invoer!F47="Aflossingsvrij",Invoer!F38="30 jaar"),360,F21) -> 360 | G30: =IF(OR(Invoer!G47="Aflossingsvrij",Invoer!G38="30 jaar"),360,G21) -> 360 | H30: =IF(OR(Invoer!H47="Aflossingsvrij",Invoer!H38="30 jaar"),360,H21) -> 360 | I30: =IF(OR(Invoer!I47="Aflossingsvrij",Invoer!I38="30 jaar"),360,I21) -> 360 | J30: =IF(OR(Invoer!J47="Aflossingsvrij",Invoer!J38="30 jaar"),360,J21) -> 360 | ... M30: =IF(OR(Invoer!M47="Aflossingsvrij",Invoer!M38="30 jaar"),360,M21) -> 360
A31: Deel 2: toetslast (annuïteit) | B31: € p/m | C31: =IF(C27<=0,0,IF(C29=0,C27/C30,C27*(C29/12)/(1-(1+C29/12)^(-C30)))) -> 1283.0345 | D31: =IF(D27<=0,0,IF(D29=0,D27/D30,D27*(D29/12)/(1-(1+D29/12)^(-D30)))) -> 1283.0345 | E31: =IF(E27<=0,0,IF(E29=0,E27/E30,E27*(E29/12)/(1-(1+E29/12)^(-E30)))) -> 1901.794 | F31: =IF(F27<=0,0,IF(F29=0,F27/F30,F27*(F29/12)/(1-(1+F29/12)^(-F30)))) -> 1283.0345 | G31: =IF(G27<=0,0,IF(G29=0,G27/G30,G27*(G29/12)/(1-(1+G29/12)^(-G30)))) -> 1283.0345 | H31: =IF(H27<=0,0,IF(H29=0,H27/H30,H27*(H29/12)/(1-(1+H29/12)^(-H30)))) -> 1283.0345 | I31: =IF(I27<=0,0,IF(I29=0,I27/I30,I27*(I29/12)/(1-(1+I29/12)^(-I30)))) -> 1283.0345 | J31: =IF(J27<=0,0,IF(J29=0,J27/J30,J27*(J29/12)/(1-(1+J29/12)^(-J30)))) -> 1283.0345 | ... M31: =IF(M27<=0,0,IF(M29=0,M27/M30,M27*(M29/12)/(1-(1+M29/12)^(-M30)))) -> 1283.0345
A32: Deel 3: restsaldo | B32: € | C32: =Invoer!C53 -> 0 | D32: =Invoer!D53 -> 0 | E32: =Invoer!E53 -> 0 | F32: =Invoer!F53 -> 0 | G32: =Invoer!G53 -> 0 | H32: =Invoer!H53 -> 0 | I32: =Invoer!I53 -> 0 | J32: =Invoer!J53 -> 0 | ... M32: =Invoer!M53 -> 0
A33: Deel 3: resterende rentevaste periode | B33: maanden | C33: =MAX(0,Invoer!C55*12-C20) -> 52 | D33: =MAX(0,Invoer!D55*12-D20) -> 52 | E33: =MAX(0,Invoer!E55*12-E20) -> 52 | F33: =MAX(0,Invoer!F55*12-F20) -> 52 | G33: =MAX(0,Invoer!G55*12-G20) -> 52 | H33: =MAX(0,Invoer!H55*12-H20) -> 52 | I33: =MAX(0,Invoer!I55*12-I20) -> 52 | J33: =MAX(0,Invoer!J55*12-J20) -> 52 | ... M33: =MAX(0,Invoer!M55*12-M20) -> 52
A34: Deel 3: toetsrente | B34: % | C34: =IF(C32>0,IF(C33<120,MAX(AFM_Toetsrente,Invoer!C54),Invoer!C54),0) -> 0 | D34: =IF(D32>0,IF(D33<120,MAX(AFM_Toetsrente,Invoer!D54),Invoer!D54),0) -> 0 | E34: =IF(E32>0,IF(E33<120,MAX(AFM_Toetsrente,Invoer!E54),Invoer!E54),0) -> 0 | F34: =IF(F32>0,IF(F33<120,MAX(AFM_Toetsrente,Invoer!F54),Invoer!F54),0) -> 0 | G34: =IF(G32>0,IF(G33<120,MAX(AFM_Toetsrente,Invoer!G54),Invoer!G54),0) -> 0 | H34: =IF(H32>0,IF(H33<120,MAX(AFM_Toetsrente,Invoer!H54),Invoer!H54),0) -> 0 | I34: =IF(I32>0,IF(I33<120,MAX(AFM_Toetsrente,Invoer!I54),Invoer!I54),0) -> 0 | J34: =IF(J32>0,IF(J33<120,MAX(AFM_Toetsrente,Invoer!J54),Invoer!J54),0) -> 0 | ... M34: =IF(M32>0,IF(M33<120,MAX(AFM_Toetsrente,Invoer!M54),Invoer!M54),0) -> 0
A35: Deel 3: toetslooptijd | B35: maanden | C35: =IF(OR(Invoer!C52="Aflossingsvrij",Invoer!C38="30 jaar"),360,C21) -> 292 | D35: =IF(OR(Invoer!D52="Aflossingsvrij",Invoer!D38="30 jaar"),360,D21) -> 360 | E35: =IF(OR(Invoer!E52="Aflossingsvrij",Invoer!E38="30 jaar"),360,E21) -> 292 | F35: =IF(OR(Invoer!F52="Aflossingsvrij",Invoer!F38="30 jaar"),360,F21) -> 292 | G35: =IF(OR(Invoer!G52="Aflossingsvrij",Invoer!G38="30 jaar"),360,G21) -> 292 | H35: =IF(OR(Invoer!H52="Aflossingsvrij",Invoer!H38="30 jaar"),360,H21) -> 292 | I35: =IF(OR(Invoer!I52="Aflossingsvrij",Invoer!I38="30 jaar"),360,I21) -> 292 | J35: =IF(OR(Invoer!J52="Aflossingsvrij",Invoer!J38="30 jaar"),360,J21) -> 292 | ... M35: =IF(OR(Invoer!M52="Aflossingsvrij",Invoer!M38="30 jaar"),360,M21) -> 292
A36: Deel 3: toetslast (annuïteit) | B36: € p/m | C36: =IF(C32<=0,0,IF(C34=0,C32/C35,C32*(C34/12)/(1-(1+C34/12)^(-C35)))) -> 0 | D36: =IF(D32<=0,0,IF(D34=0,D32/D35,D32*(D34/12)/(1-(1+D34/12)^(-D35)))) -> 0 | E36: =IF(E32<=0,0,IF(E34=0,E32/E35,E32*(E34/12)/(1-(1+E34/12)^(-E35)))) -> 0 | F36: =IF(F32<=0,0,IF(F34=0,F32/F35,F32*(F34/12)/(1-(1+F34/12)^(-F35)))) -> 0 | G36: =IF(G32<=0,0,IF(G34=0,G32/G35,G32*(G34/12)/(1-(1+G34/12)^(-G35)))) -> 0 | H36: =IF(H32<=0,0,IF(H34=0,H32/H35,H32*(H34/12)/(1-(1+H34/12)^(-H35)))) -> 0 | I36: =IF(I32<=0,0,IF(I34=0,I32/I35,I32*(I34/12)/(1-(1+I34/12)^(-I35)))) -> 0 | J36: =IF(J32<=0,0,IF(J34=0,J32/J35,J32*(J34/12)/(1-(1+J34/12)^(-J35)))) -> 0 | ... M36: =IF(M32<=0,0,IF(M34=0,M32/M35,M32*(M34/12)/(1-(1+M34/12)^(-M35)))) -> 0
A37: Deel 4: restsaldo | B37: € | C37: =Invoer!C58 -> 0 | D37: =Invoer!D58 -> 0 | E37: =Invoer!E58 -> 0 | F37: =Invoer!F58 -> 0 | G37: =Invoer!G58 -> 0 | H37: =Invoer!H58 -> 0 | I37: =Invoer!I58 -> 0 | J37: =Invoer!J58 -> 0 | ... M37: =Invoer!M58 -> 0
A38: Deel 4: resterende rentevaste periode | B38: maanden | C38: =MAX(0,Invoer!C60*12-C20) -> 52 | D38: =MAX(0,Invoer!D60*12-D20) -> 52 | E38: =MAX(0,Invoer!E60*12-E20) -> 52 | F38: =MAX(0,Invoer!F60*12-F20) -> 52 | G38: =MAX(0,Invoer!G60*12-G20) -> 52 | H38: =MAX(0,Invoer!H60*12-H20) -> 52 | I38: =MAX(0,Invoer!I60*12-I20) -> 52 | J38: =MAX(0,Invoer!J60*12-J20) -> 52 | ... M38: =MAX(0,Invoer!M60*12-M20) -> 52
A39: Deel 4: toetsrente | B39: % | C39: =IF(C37>0,IF(C38<120,MAX(AFM_Toetsrente,Invoer!C59),Invoer!C59),0) -> 0 | D39: =IF(D37>0,IF(D38<120,MAX(AFM_Toetsrente,Invoer!D59),Invoer!D59),0) -> 0 | E39: =IF(E37>0,IF(E38<120,MAX(AFM_Toetsrente,Invoer!E59),Invoer!E59),0) -> 0 | F39: =IF(F37>0,IF(F38<120,MAX(AFM_Toetsrente,Invoer!F59),Invoer!F59),0) -> 0 | G39: =IF(G37>0,IF(G38<120,MAX(AFM_Toetsrente,Invoer!G59),Invoer!G59),0) -> 0 | H39: =IF(H37>0,IF(H38<120,MAX(AFM_Toetsrente,Invoer!H59),Invoer!H59),0) -> 0 | I39: =IF(I37>0,IF(I38<120,MAX(AFM_Toetsrente,Invoer!I59),Invoer!I59),0) -> 0 | J39: =IF(J37>0,IF(J38<120,MAX(AFM_Toetsrente,Invoer!J59),Invoer!J59),0) -> 0 | ... M39: =IF(M37>0,IF(M38<120,MAX(AFM_Toetsrente,Invoer!M59),Invoer!M59),0) -> 0
A40: Deel 4: toetslooptijd | B40: maanden | C40: =IF(OR(Invoer!C57="Aflossingsvrij",Invoer!C38="30 jaar"),360,C21) -> 292 | D40: =IF(OR(Invoer!D57="Aflossingsvrij",Invoer!D38="30 jaar"),360,D21) -> 360 | E40: =IF(OR(Invoer!E57="Aflossingsvrij",Invoer!E38="30 jaar"),360,E21) -> 292 | F40: =IF(OR(Invoer!F57="Aflossingsvrij",Invoer!F38="30 jaar"),360,F21) -> 292 | G40: =IF(OR(Invoer!G57="Aflossingsvrij",Invoer!G38="30 jaar"),360,G21) -> 292 | H40: =IF(OR(Invoer!H57="Aflossingsvrij",Invoer!H38="30 jaar"),360,H21) -> 292 | I40: =IF(OR(Invoer!I57="Aflossingsvrij",Invoer!I38="30 jaar"),360,I21) -> 292 | J40: =IF(OR(Invoer!J57="Aflossingsvrij",Invoer!J38="30 jaar"),360,J21) -> 292 | ... M40: =IF(OR(Invoer!M57="Aflossingsvrij",Invoer!M38="30 jaar"),360,M21) -> 292
A41: Deel 4: toetslast (annuïteit) | B41: € p/m | C41: =IF(C37<=0,0,IF(C39=0,C37/C40,C37*(C39/12)/(1-(1+C39/12)^(-C40)))) -> 0 | D41: =IF(D37<=0,0,IF(D39=0,D37/D40,D37*(D39/12)/(1-(1+D39/12)^(-D40)))) -> 0 | E41: =IF(E37<=0,0,IF(E39=0,E37/E40,E37*(E39/12)/(1-(1+E39/12)^(-E40)))) -> 0 | F41: =IF(F37<=0,0,IF(F39=0,F37/F40,F37*(F39/12)/(1-(1+F39/12)^(-F40)))) -> 0 | G41: =IF(G37<=0,0,IF(G39=0,G37/G40,G37*(G39/12)/(1-(1+G39/12)^(-G40)))) -> 0 | H41: =IF(H37<=0,0,IF(H39=0,H37/H40,H37*(H39/12)/(1-(1+H39/12)^(-H40)))) -> 0 | I41: =IF(I37<=0,0,IF(I39=0,I37/I40,I37*(I39/12)/(1-(1+I39/12)^(-I40)))) -> 0 | J41: =IF(J37<=0,0,IF(J39=0,J37/J40,J37*(J39/12)/(1-(1+J39/12)^(-J40)))) -> 0 | ... M41: =IF(M37<=0,0,IF(M39=0,M37/M40,M37*(M39/12)/(1-(1+M39/12)^(-M40)))) -> 0
...

Sheet Solver
A1: Solver: samengestelde toets met gewogen toetsrente
A2: De woonquote hangt af van de gewogen toetsrente van alle leningdelen, en die beweegt mee met het nieuwe bedrag. Per rentekolom wordt het bereik van bedragen bepaald waarin die kolom geldt; het hoogste haalbare bedrag wint.
A4: Stap | B4: Eenheid | C4: =Invoer!C4 -> 1 | D4: =Invoer!D4 -> 2 | E4: =Invoer!E4 -> 3 | F4: =Invoer!F4 -> 4 | G4: =Invoer!G4 -> 5 | H4: =Invoer!H4 -> 6 | I4: =Invoer!I4 -> 7 | J4: =Invoer!J4 -> 8 | ... M4: =Invoer!M4 -> 11
A5: Blok A: inkomensscenario (tabel 1)
A6: Toetsinkomen | B6: € | C6: =Berekening!C9 -> 225000 | D6: =Berekening!D9 -> 225000 | E6: =Berekening!E9 -> 225000 | F6: =Berekening!F9 -> 225000 | G6: =Berekening!G9 -> 60000 | H6: =Berekening!H9 -> 150000 | I6: =Berekening!I9 -> 225000 | J6: =Berekening!J9 -> 225000 | ... M6: =Berekening!M9 -> 225000
A7: Bonussen buiten de woonlast (energie + alleenstaand) | B7: € | C7: =Berekening!C87+Berekening!C86 -> 10000 | D7: =Berekening!D87+Berekening!D86 -> 10000 | E7: =Berekening!E87+Berekening!E86 -> 10000 | F7: =Berekening!F87+Berekening!F86 -> 10000 | G7: =Berekening!G87+Berekening!G86 -> 22000 | H7: =Berekening!H87+Berekening!H86 -> 10000 | I7: =Berekening!I87+Berekening!I86 -> 10000 | J7: =Berekening!J87+Berekening!J86 -> 10000 | ... M7: =Berekening!M87+Berekening!M86 -> 10000
A8: Kolom 1: woonquote | B8: % | C8: =INDEX(T1_Tabel,Berekening!C80,1)+(Berekening!C79-INDEX(T1_Inkomen,Berekening!C80))/(INDEX(T1_Inkomen,Berekening!C80+1)-INDEX(T1_Inkomen,Berekening!C80))*(INDEX(T1_Tabel,Berekening!C80+1,1)-INDEX(T1_Tabel,Berekening!C80,1)) -> 0.222 | D8: =INDEX(T1_Tabel,Berekening!D80,1)+(Berekening!D79-INDEX(T1_Inkomen,Berekening!D80))/(INDEX(T1_Inkomen,Berekening!D80+1)-INDEX(T1_Inkomen,Berekening!D80))*(INDEX(T1_Tabel,Berekening!D80+1,1)-INDEX(T1_Tabel,Berekening!D80,1)) -> 0.222 | E8: =INDEX(T1_Tabel,Berekening!E80,1)+(Berekening!E79-INDEX(T1_Inkomen,Berekening!E80))/(INDEX(T1_Inkomen,Berekening!E80+1)-INDEX(T1_Inkomen,Berekening!E80))*(INDEX(T1_Tabel,Berekening!E80+1,1)-INDEX(T1_Tabel,Berekening!E80,1)) -> 0.222 | F8: =INDEX(T1_Tabel,Berekening!F80,1)+(Berekening!F79-INDEX(T1_Inkomen,Berekening!F80))/(INDEX(T1_Inkomen,Berekening!F80+1)-INDEX(T1_Inkomen,Berekening!F80))*(INDEX(T1_Tabel,Berekening!F80+1,1)-INDEX(T1_Tabel,Berekening!F80,1)) -> 0.222 | G8: =INDEX(T1_Tabel,Berekening!G80,1)+(Berekening!G79-INDEX(T1_Inkomen,Berekening!G80))/(INDEX(T1_Inkomen,Berekening!G80+1)-INDEX(T1_Inkomen,Berekening!G80))*(INDEX(T1_Tabel,Berekening!G80+1,1)-INDEX(T1_Tabel,Berekening!G80,1)) -> 0.177 | H8: =INDEX(T1_Tabel,Berekening!H80,1)+(Berekening!H79-INDEX(T1_Inkomen,Berekening!H80))/(INDEX(T1_Inkomen,Berekening!H80+1)-INDEX(T1_Inkomen,Berekening!H80))*(INDEX(T1_Tabel,Berekening!H80+1,1)-INDEX(T1_Tabel,Berekening!H80,1)) -> 0.222 | I8: =INDEX(T1_Tabel,Berekening!I80,1)+(Berekening!I79-INDEX(T1_Inkomen,Berekening!I80))/(INDEX(T1_Inkomen,Berekening!I80+1)-INDEX(T1_Inkomen,Berekening!I80))*(INDEX(T1_Tabel,Berekening!I80+1,1)-INDEX(T1_Tabel,Berekening!I80,1)) -> 0.222 | J8: =INDEX(T1_Tabel,Berekening!J80,1)+(Berekening!J79-INDEX(T1_Inkomen,Berekening!J80))/(INDEX(T1_Inkomen,Berekening!J80+1)-INDEX(T1_Inkomen,Berekening!J80))*(INDEX(T1_Tabel,Berekening!J80+1,1)-INDEX(T1_Tabel,Berekening!J80,1)) -> 0.222 | ... M8: =INDEX(T1_Tabel,Berekening!M80,1)+(Berekening!M79-INDEX(T1_Inkomen,Berekening!M80))/(INDEX(T1_Inkomen,Berekening!M80+1)-INDEX(T1_Inkomen,Berekening!M80))*(INDEX(T1_Tabel,Berekening!M80+1,1)-INDEX(T1_Tabel,Berekening!M80,1)) -> 0.222
A9: Kolom 1: bedrag als de woonquote van deze kolom geldt | B9: € | C9: =MAX(0,(C8*C6/12-Berekening!C18-Berekening!C44)*Berekening!C11-Berekening!C75+C7) -> 140141.65 | D9: =MAX(0,(D8*D6/12-Berekening!D18-Berekening!D44)*Berekening!D11-Berekening!D75+D7) -> 169193.2 | E9: =MAX(0,(E8*E6/12-Berekening!E18-Berekening!E44)*Berekening!E11-Berekening!E75+E7) -> 17494.106 | F9: =MAX(0,(F8*F6/12-Berekening!F18-Berekening!F44)*Berekening!F11-Berekening!F75+F7) -> 135587.68 | G9: =MAX(0,(G8*G6/12-Berekening!G18-Berekening!G44)*Berekening!G11-Berekening!G75+G7) -> 192837.24 | H9: =MAX(0,(H8*H6/12-Berekening!H18-Berekening!H44)*Berekening!H11-Berekening!H75+H7) -> 515562.42 | I9: =MAX(0,(I8*I6/12-Berekening!I18-Berekening!I44)*Berekening!I11-Berekening!I75+I7) -> 692913.56 | J9: =MAX(0,(J8*J6/12-Berekening!J18-Berekening!J44)*Berekening!J11-Berekening!J75+J7) -> 177427.72 | ... M9: =MAX(0,(M8*M6/12-Berekening!M18-Berekening!M44)*Berekening!M11-Berekening!M75+M7) -> 140141.65
A10: Kolom 1: laagste bedrag waarbij de gewogen rente in deze kolom valt | B10: € | C10: =MAX(0,IF((INDEX(T1_Rente,1)+0.000005)>Berekening!C10,(Berekening!C45-(INDEX(T1_Rente,1)+0.000005)*Berekening!C46)/(360*((INDEX(T1_Rente,1)+0.000005)-Berekening!C10)),IF((INDEX(T1_Rente,1)+0.000005)=Berekening!C10,IF(Berekening!C45-(INDEX(T1_Rente,1)+0.000005)*Berekening!C46<=0,-1000000000000,1000000000000),-1000000000000))) -> 0 | D10: =MAX(0,IF((INDEX(T1_Rente,1)+0.000005)>Berekening!D10,(Berekening!D45-(INDEX(T1_Rente,1)+0.000005)*Berekening!D46)/(360*((INDEX(T1_Rente,1)+0.000005)-Berekening!D10)),IF((INDEX(T1_Rente,1)+0.000005)=Berekening!D10,IF(Berekening!D45-(INDEX(T1_Rente,1)+0.000005)*Berekening!D46<=0,-1000000000000,1000000000000),-1000000000000))) -> 0 | E10: =MAX(0,IF((INDEX(T1_Rente,1)+0.000005)>Berekening!E10,(Berekening!E45-(INDEX(T1_Rente,1)+0.000005)*Berekening!E46)/(360*((INDEX(T1_Rente,1)+0.000005)-Berekening!E10)),IF((INDEX(T1_Rente,1)+0.000005)=Berekening!E10,IF(Berekening!E45-(INDEX(T1_Rente,1)+0.000005)*Berekening!E46<=0,-1000000000000,1000000000000),-1000000000000))) -> 0 | F10: =MAX(0,IF((INDEX(T1_Rente,1)+0.000005)>Berekening!F10,(Berekening!F45-(INDEX(T1_Rente,1)+0.000005)*Berekening!F46)/(360*((INDEX(T1_Rente,1)+0.000005)-Berekening!F10)),IF((INDEX(T1_Rente,1)+0.000005)=Berekening!F10,IF(Berekening!F45-(INDEX(T1_Rente,1)+0.000005)*Berekening!F46<=0,-1000000000000,1000000000000),-1000000000000))) -> 0 | G10: =MAX(0,IF((INDEX(T1_Rente,1)+0.000005)>Berekening!G10,(Berekening!G45-(INDEX(T1_Rente,1)+0.000005)*Berekening!G46)/(360*((INDEX(T1_Rente,1)+0.000005)-Berekening!G10)),IF((INDEX(T1_Rente,1)+0.000005)=Berekening!G10,IF(Berekening!G45-(INDEX(T1_Rente,1)+0.000005)*Berekening!G46<=0,-1000000000000,1000000000000),-1000000000000))) -> 0 | H10: =MAX(0,IF((INDEX(T1_Rente,1)+0.000005)>Berekening!H10,(Berekening!H45-(INDEX(T1_Rente,1)+0.000005)*Berekening!H46)/(360*((INDEX(T1_Rente,1)+0.000005)-Berekening!H10)),IF((INDEX(T1_Rente,1)+0.000005)=Berekening!H10,IF(Berekening!H45-(INDEX(T1_Rente,1)+0.000005)*Berekening!H46<=0,-1000000000000,1000000000000),-1000000000000))) -> 0 | I10: =MAX(0,IF((INDEX(T1_Rente,1)+0.000005)>Berekening!I10,(Berekening!I45-(INDEX(T1_Rente,1)+0.000005)*Berekening!I46)/(360*((INDEX(T1_Rente,1)+0.000005)-Berekening!I10)),IF((INDEX(T1_Rente,1)+0.000005)=Berekening!I10,IF(Berekening!I45-(INDEX(T1_Rente,1)+0.000005)*Berekening!I46<=0,-1000000000000,1000000000000),-1000000000000))) -> 0 | J10: =MAX(0,IF((INDEX(T1_Rente,1)+0.000005)>Berekening!J10,(Berekening!J45-(INDEX(T1_Rente,1)+0.000005)*Berekening!J46)/(360*((INDEX(T1_Rente,1)+0.000005)-Berekening!J10)),IF((INDEX(T1_Rente,1)+0.000005)=Berekening!J10,IF(Berekening!J45-(INDEX(T1_Rente,1)+0.000005)*Berekening!J46<=0,-1000000000000,1000000000000),-1000000000000))) -> 0 | ... M10: =MAX(0,IF((INDEX(T1_Rente,1)+0.000005)>Berekening!M10,(Berekening!M45-(INDEX(T1_Rente,1)+0.000005)*Berekening!M46)/(360*((INDEX(T1_Rente,1)+0.000005)-Berekening!M10)),IF((INDEX(T1_Rente,1)+0.000005)=Berekening!M10,IF(Berekening!M45-(INDEX(T1_Rente,1)+0.000005)*Berekening!M46<=0,-1000000000000,1000000000000),-1000000000000))) -> 0
A11: Kolom 1: hoogste bedrag waarbij de gewogen rente in deze kolom valt | B11: € | C11: =MIN(1000000000000,IF((INDEX(T1_Rente,1)+0.000005)<Berekening!C10,(Berekening!C45-(INDEX(T1_Rente,1)+0.000005)*Berekening!C46)/(360*((INDEX(T1_Rente,1)+0.000005)-Berekening!C10)),1000000000000)) -> -278643.49 | D11: =MIN(1000000000000,IF((INDEX(T1_Rente,1)+0.000005)<Berekening!D10,(Berekening!D45-(INDEX(T1_Rente,1)+0.000005)*Berekening!D46)/(360*((INDEX(T1_Rente,1)+0.000005)-Berekening!D10)),1000000000000)) -> -334492.74 | E11: =MIN(1000000000000,IF((INDEX(T1_Rente,1)+0.000005)<Berekening!E10,(Berekening!E45-(INDEX(T1_Rente,1)+0.000005)*Berekening!E46)/(360*((INDEX(T1_Rente,1)+0.000005)-Berekening!E10)),1000000000000)) -> -628525.35 | F11: =MIN(1000000000000,IF((INDEX(T1_Rente,1)+0.000005)<Berekening!F10,(Berekening!F45-(INDEX(T1_Rente,1)+0.000005)*Berekening!F46)/(360*((INDEX(T1_Rente,1)+0.000005)-Berekening!F10)),1000000000000)) -> -253960.11 | G11: =MIN(1000000000000,IF((INDEX(T1_Rente,1)+0.000005)<Berekening!G10,(Berekening!G45-(INDEX(T1_Rente,1)+0.000005)*Berekening!G46)/(360*((INDEX(T1_Rente,1)+0.000005)-Berekening!G10)),1000000000000)) -> 0 | H11: =MIN(1000000000000,IF((INDEX(T1_Rente,1)+0.000005)<Berekening!H10,(Berekening!H45-(INDEX(T1_Rente,1)+0.000005)*Berekening!H46)/(360*((INDEX(T1_Rente,1)+0.000005)-Berekening!H10)),1000000000000)) -> 0 | I11: =MIN(1000000000000,IF((INDEX(T1_Rente,1)+0.000005)<Berekening!I10,(Berekening!I45-(INDEX(T1_Rente,1)+0.000005)*Berekening!I46)/(360*((INDEX(T1_Rente,1)+0.000005)-Berekening!I10)),1000000000000)) -> 0 | J11: =MIN(1000000000000,IF((INDEX(T1_Rente,1)+0.000005)<Berekening!J10,(Berekening!J45-(INDEX(T1_Rente,1)+0.000005)*Berekening!J46)/(360*((INDEX(T1_Rente,1)+0.000005)-Berekening!J10)),1000000000000)) -> -278643.49 | ... M11: =MIN(1000000000000,IF((INDEX(T1_Rente,1)+0.000005)<Berekening!M10,(Berekening!M45-(INDEX(T1_Rente,1)+0.000005)*Berekening!M46)/(360*((INDEX(T1_Rente,1)+0.000005)-Berekening!M10)),1000000000000)) -> -278643.49
A12: Kolom 1: haalbaar bedrag (−1 = onmogelijk) | B12: € | C12: =IF(C10>C11,-1,IF(C9<C10-0.000000001,-1,IF(C9>C11,MAX(C10,C11-1),C9))) -> -1 | D12: =IF(D10>D11,-1,IF(D9<D10-0.000000001,-1,IF(D9>D11,MAX(D10,D11-1),D9))) -> -1 | E12: =IF(E10>E11,-1,IF(E9<E10-0.000000001,-1,IF(E9>E11,MAX(E10,E11-1),E9))) -> -1 | F12: =IF(F10>F11,-1,IF(F9<F10-0.000000001,-1,IF(F9>F11,MAX(F10,F11-1),F9))) -> -1 | G12: =IF(G10>G11,-1,IF(G9<G10-0.000000001,-1,IF(G9>G11,MAX(G10,G11-1),G9))) -> 0 | H12: =IF(H10>H11,-1,IF(H9<H10-0.000000001,-1,IF(H9>H11,MAX(H10,H11-1),H9))) -> 0 | I12: =IF(I10>I11,-1,IF(I9<I10-0.000000001,-1,IF(I9>I11,MAX(I10,I11-1),I9))) -> 0 | J12: =IF(J10>J11,-1,IF(J9<J10-0.000000001,-1,IF(J9>J11,MAX(J10,J11-1),J9))) -> -1 | ... M12: =IF(M10>M11,-1,IF(M9<M10-0.000000001,-1,IF(M9>M11,MAX(M10,M11-1),M9))) -> -1
A13: Kolom 2: woonquote | B13: % | C13: =INDEX(T1_Tabel,Berekening!C80,2)+(Berekening!C79-INDEX(T1_Inkomen,Berekening!C80))/(INDEX(T1_Inkomen,Berekening!C80+1)-INDEX(T1_Inkomen,Berekening!C80))*(INDEX(T1_Tabel,Berekening!C80+1,2)-INDEX(T1_Tabel,Berekening!C80,2)) -> 0.233 | D13: =INDEX(T1_Tabel,Berekening!D80,2)+(Berekening!D79-INDEX(T1_Inkomen,Berekening!D80))/(INDEX(T1_Inkomen,Berekening!D80+1)-INDEX(T1_Inkomen,Berekening!D80))*(INDEX(T1_Tabel,Berekening!D80+1,2)-INDEX(T1_Tabel,Berekening!D80,2)) -> 0.233 | E13: =INDEX(T1_Tabel,Berekening!E80,2)+(Berekening!E79-INDEX(T1_Inkomen,Berekening!E80))/(INDEX(T1_Inkomen,Berekening!E80+1)-INDEX(T1_Inkomen,Berekening!E80))*(INDEX(T1_Tabel,Berekening!E80+1,2)-INDEX(T1_Tabel,Berekening!E80,2)) -> 0.233 | F13: =INDEX(T1_Tabel,Berekening!F80,2)+(Berekening!F79-INDEX(T1_Inkomen,Berekening!F80))/(INDEX(T1_Inkomen,Berekening!F80+1)-INDEX(T1_Inkomen,Berekening!F80))*(INDEX(T1_Tabel,Berekening!F80+1,2)-INDEX(T1_Tabel,Berekening!F80,2)) -> 0.233 | G13: =INDEX(T1_Tabel,Berekening!G80,2)+(Berekening!G79-INDEX(T1_Inkomen,Berekening!G80))/(INDEX(T1_Inkomen,Berekening!G80+1)-INDEX(T1_Inkomen,Berekening!G80))*(INDEX(T1_Tabel,Berekening!G80+1,2)-INDEX(T1_Tabel,Berekening!G80,2)) -> 0.187 | H13: =INDEX(T1_Tabel,Berekening!H80,2)+(Berekening!H79-INDEX(T1_Inkomen,Berekening!H80))/(INDEX(T1_Inkomen,Berekening!H80+1)-INDEX(T1_Inkomen,Berekening!H80))*(INDEX(T1_Tabel,Berekening!H80+1,2)-INDEX(T1_Tabel,Berekening!H80,2)) -> 0.233 | I13: =INDEX(T1_Tabel,Berekening!I80,2)+(Berekening!I79-INDEX(T1_Inkomen,Berekening!I80))/(INDEX(T1_Inkomen,Berekening!I80+1)-INDEX(T1_Inkomen,Berekening!I80))*(INDEX(T1_Tabel,Berekening!I80+1,2)-INDEX(T1_Tabel,Berekening!I80,2)) -> 0.233 | J13: =INDEX(T1_Tabel,Berekening!J80,2)+(Berekening!J79-INDEX(T1_Inkomen,Berekening!J80))/(INDEX(T1_Inkomen,Berekening!J80+1)-INDEX(T1_Inkomen,Berekening!J80))*(INDEX(T1_Tabel,Berekening!J80+1,2)-INDEX(T1_Tabel,Berekening!J80,2)) -> 0.233 | ... M13: =INDEX(T1_Tabel,Berekening!M80,2)+(Berekening!M79-INDEX(T1_Inkomen,Berekening!M80))/(INDEX(T1_Inkomen,Berekening!M80+1)-INDEX(T1_Inkomen,Berekening!M80))*(INDEX(T1_Tabel,Berekening!M80+1,2)-INDEX(T1_Tabel,Berekening!M80,2)) -> 0.233
A14: Kolom 2: bedrag als de woonquote van deze kolom geldt | B14: € | C14: =MAX(0,(C13*C6/12-Berekening!C18-Berekening!C44)*Berekening!C11-Berekening!C75+C7) -> 179955.41 | D14: =MAX(0,(D13*D6/12-Berekening!D18-Berekening!D44)*Berekening!D11-Berekening!D75+D7) -> 209006.96 | E14: =MAX(0,(E13*E6/12-Berekening!E18-Berekening!E44)*Berekening!E11-Berekening!E75+E7) -> 57307.87 | F14: =MAX(0,(F13*F6/12-Berekening!F18-Berekening!F44)*Berekening!F11-Berekening!F75+F7) -> 174008.26 | G14: =MAX(0,(G13*G6/12-Berekening!G18-Berekening!G44)*Berekening!G11-Berekening!G75+G7) -> 202489.06 | H14: =MAX(0,(H13*H6/12-Berekening!H18-Berekening!H44)*Berekening!H11-Berekening!H75+H7) -> 542104.93 | I14: =MAX(0,(I13*I6/12-Berekening!I18-Berekening!I44)*Berekening!I11-Berekening!I75+I7) -> 732727.32 | J14: =MAX(0,(J13*J6/12-Berekening!J18-Berekening!J44)*Berekening!J11-Berekening!J75+J7) -> 217241.48 | ... M14: =MAX(0,(M13*M6/12-Berekening!M18-Berekening!M44)*Berekening!M11-Berekening!M75+M7) -> 179955.41
A15: Kolom 2: laagste bedrag waarbij de gewogen rente in deze kolom valt | B15: € | C15: =MAX(0,IF((INDEX(T1_Rente,2)+0.000005)>Berekening!C10,(Berekening!C45-(INDEX(T1_Rente,2)+0.000005)*Berekening!C46)/(360*((INDEX(T1_Rente,2)+0.000005)-Berekening!C10)),IF((INDEX(T1_Rente,2)+0.000005)=Berekening!C10,IF(Berekening!C45-(INDEX(T1_Rente,2)+0.000005)*Berekening!C46<=0,-1000000000000,1000000000000),-1000000000000)),IF((INDEX(T1_Rente,2)-0.005+0.000005)<Berekening!C10,(Berekening!C45-(INDEX(T1_Rente,2)-0.005+0.000005)*Berekening!C46)/(360*((INDEX(T1_Rente,2)-0.005+0.000005)-Berekening!C10)),IF((INDEX(T1_Rente,2)-0.005+0.000005)=Berekening!C10,IF(Berekening!C45-(INDEX(T1_Rente,2)-0.005+0.000005)*Berekening!C46>0,-1000000000000,1000000000000),-1000000000000))) -> 0 | D15: =MAX(0,IF((INDEX(T1_Rente,2)+0.000005)>Berekening!D10,(Berekening!D45-(INDEX(T1_Rente,2)+0.000005)*Berekening!D46)/(360*((INDEX(T1_Rente,2)+0.000005)-Berekening!D10)),IF((INDEX(T1_Rente,2)+0.000005)=Berekening!D10,IF(Berekening!D45-(INDEX(T1_Rente,2)+0.000005)*Berekening!D46<=0,-1000000000000,1000000000000),-1000000000000)),IF((INDEX(T1_Rente,2)-0.005+0.000005)<Berekening!D10,(Berekening!D45-(INDEX(T1_Rente,2)-0.005+0.000005)*Berekening!D46)/(360*((INDEX(T1_Rente,2)-0.005+0.000005)-Berekening!D10)),IF((INDEX(T1_Rente,2)-0.005+0.000005)=Berekening!D10,IF(Berekening!D45-(INDEX(T1_Rente,2)-0.005+0.000005)*Berekening!D46>0,-1000000000000,1000000000000),-1000000000000))) -> 0 | E15: =MAX(0,IF((INDEX(T1_Rente,2)+0.000005)>Berekening!E10,(Berekening!E45-(INDEX(T1_Rente,2)+0.000005)*Berekening!E46)/(360*((INDEX(T1_Rente,2)+0.000005)-Berekening!E10)),IF((INDEX(T1_Rente,2)+0.000005)=Berekening!E10,IF(Berekening!E45-(INDEX(T1_Rente,2)+0.000005)*Berekening!E46<=0,-1000000000000,1000000000000),-1000000000000)),IF((INDEX(T1_Rente,2)-0.005+0.000005)<Berekening!E10,(Berekening!E45-(INDEX(T1_Rente,2)-0.005+0.000005)*Berekening!E46)/(360*((INDEX(T1_Rente,2)-0.005+0.000005)-Berekening!E10)),IF((INDEX(T1_Rente,2)-0.005+0.000005)=Berekening!E10,IF(Berekening!E45-(INDEX(T1_Rente,2)-0.005+0.000005)*Berekening!E46>0,-1000000000000,1000000000000),-1000000000000))) -> 0 | F15: =MAX(0,IF((INDEX(T1_Rente,2)+0.000005)>Berekening!F10,(Berekening!F45-(INDEX(T1_Rente,2)+0.000005)*Berekening!F46)/(360*((INDEX(T1_Rente,2)+0.000005)-Berekening!F10)),IF((INDEX(T1_Rente,2)+0.000005)=Berekening!F10,IF(Berekening!F45-(INDEX(T1_Rente,2)+0.000005)*Berekening!F46<=0,-1000000000000,1000000000000),-1000000000000)),IF((INDEX(T1_Rente,2)-0.005+0.000005)<Berekening!F10,(Berekening!F45-(INDEX(T1_Rente,2)-0.005+0.000005)*Berekening!F46)/(360*((INDEX(T1_Rente,2)-0.005+0.000005)-Berekening!F10)),IF((INDEX(T1_Rente,2)-0.005+0.000005)=Berekening!F10,IF(Berekening!F45-(INDEX(T1_Rente,2)-0.005+0.000005)*Berekening!F46>0,-1000000000000,1000000000000),-1000000000000))) -> 0 | G15: =MAX(0,IF((INDEX(T1_Rente,2)+0.000005)>Berekening!G10,(Berekening!G45-(INDEX(T1_Rente,2)+0.000005)*Berekening!G46)/(360*((INDEX(T1_Rente,2)+0.000005)-Berekening!G10)),IF((INDEX(T1_Rente,2)+0.000005)=Berekening!G10,IF(Berekening!G45-(INDEX(T1_Rente,2)+0.000005)*Berekening!G46<=0,-1000000000000,1000000000000),-1000000000000)),IF((INDEX(T1_Rente,2)-0.005+0.000005)<Berekening!G10,(Berekening!G45-(INDEX(T1_Rente,2)-0.005+0.000005)*Berekening!G46)/(360*((INDEX(T1_Rente,2)-0.005+0.000005)-Berekening!G10)),IF((INDEX(T1_Rente,2)-0.005+0.000005)=Berekening!G10,IF(Berekening!G45-(INDEX(T1_Rente,2)-0.005+0.000005)*Berekening!G46>0,-1000000000000,1000000000000),-1000000000000))) -> 0 | H15: =MAX(0,IF((INDEX(T1_Rente,2)+0.000005)>Berekening!H10,(Berekening!H45-(INDEX(T1_Rente,2)+0.000005)*Berekening!H46)/(360*((INDEX(T1_Rente,2)+0.000005)-Berekening!H10)),IF((INDEX(T1_Rente,2)+0.000005)=Berekening!H10,IF(Berekening!H45-(INDEX(T1_Rente,2)+0.000005)*Berekening!H46<=0,-1000000000000,1000000000000),-1000000000000)),IF((INDEX(T1_Rente,2)-0.005+0.000005)<Berekening!H10,(Berekening!H45-(INDEX(T1_Rente,2)-0.005+0.000005)*Berekening!H46)/(360*((INDEX(T1_Rente,2)-0.005+0.000005)-Berekening!H10)),IF((INDEX(T1_Rente,2)-0.005+0.000005)=Berekening!H10,IF(Berekening!H45-(INDEX(T1_Rente,2)-0.005+0.000005)*Berekening!H46>0,-1000000000000,1000000000000),-1000000000000))) -> 0 | I15: =MAX(0,IF((INDEX(T1_Rente,2)+0.000005)>Berekening!I10,(Berekening!I45-(INDEX(T1_Rente,2)+0.000005)*Berekening!I46)/(360*((INDEX(T1_Rente,2)+0.000005)-Berekening!I10)),IF((INDEX(T1_Rente,2)+0.000005)=Berekening!I10,IF(Berekening!I45-(INDEX(T1_Rente,2)+0.000005)*Berekening!I46<=0,-1000000000000,1000000000000),-1000000000000)),IF((INDEX(T1_Rente,2)-0.005+0.000005)<Berekening!I10,(Berekening!I45-(INDEX(T1_Rente,2)-0.005+0.000005)*Berekening!I46)/(360*((INDEX(T1_Rente,2)-0.005+0.000005)-Berekening!I10)),IF((INDEX(T1_Rente,2)-0.005+0.000005)=Berekening!I10,IF(Berekening!I45-(INDEX(T1_Rente,2)-0.005+0.000005)*Berekening!I46>0,-1000000000000,1000000000000),-1000000000000))) -> 0 | J15: =MAX(0,IF((INDEX(T1_Rente,2)+0.000005)>Berekening!J10,(Berekening!J45-(INDEX(T1_Rente,2)+0.000005)*Berekening!J46)/(360*((INDEX(T1_Rente,2)+0.000005)-Berekening!J10)),IF((INDEX(T1_Rente,2)+0.000005)=Berekening!J10,IF(Berekening!J45-(INDEX(T1_Rente,2)+0.000005)*Berekening!J46<=0,-1000000000000,1000000000000),-1000000000000)),IF((INDEX(T1_Rente,2)-0.005+0.000005)<Berekening!J10,(Berekening!J45-(INDEX(T1_Rente,2)-0.005+0.000005)*Berekening!J46)/(360*((INDEX(T1_Rente,2)-0.005+0.000005)-Berekening!J10)),IF((INDEX(T1_Rente,2)-0.005+0.000005)=Berekening!J10,IF(Berekening!J45-(INDEX(T1_Rente,2)-0.005+0.000005)*Berekening!J46>0,-1000000000000,1000000000000),-1000000000000))) -> 0 | ... M15: =MAX(0,IF((INDEX(T1_Rente,2)+0.000005)>Berekening!M10,(Berekening!M45-(INDEX(T1_Rente,2)+0.000005)*Berekening!M46)/(360*((INDEX(T1_Rente,2)+0.000005)-Berekening!M10)),IF((INDEX(T1_Rente,2)+0.000005)=Berekening!M10,IF(Berekening!M45-(INDEX(T1_Rente,2)+0.000005)*Berekening!M46<=0,-1000000000000,1000000000000),-1000000000000)),IF((INDEX(T1_Rente,2)-0.005+0.000005)<Berekening!M10,(Berekening!M45-(INDEX(T1_Rente,2)-0.005+0.000005)*Berekening!M46)/(360*((INDEX(T1_Rente,2)-0.005+0.000005)-Berekening!M10)),IF((INDEX(T1_Rente,2)-0.005+0.000005)=Berekening!M10,IF(Berekening!M45-(INDEX(T1_Rente,2)-0.005+0.000005)*Berekening!M46>0,-1000000000000,1000000000000),-1000000000000))) -> 0
A16: Kolom 2: hoogste bedrag waarbij de gewogen rente in deze kolom valt | B16: € | C16: =MIN(1000000000000,IF((INDEX(T1_Rente,2)+0.000005)<Berekening!C10,(Berekening!C45-(INDEX(T1_Rente,2)+0.000005)*Berekening!C46)/(360*((INDEX(T1_Rente,2)+0.000005)-Berekening!C10)),1000000000000),IF((INDEX(T1_Rente,2)-0.005+0.000005)>Berekening!C10,(Berekening!C45-(INDEX(T1_Rente,2)-0.005+0.000005)*Berekening!C46)/(360*((INDEX(T1_Rente,2)-0.005+0.000005)-Berekening!C10)),1000000000000)) -> -223948.47 | D16: =MIN(1000000000000,IF((INDEX(T1_Rente,2)+0.000005)<Berekening!D10,(Berekening!D45-(INDEX(T1_Rente,2)+0.000005)*Berekening!D46)/(360*((INDEX(T1_Rente,2)+0.000005)-Berekening!D10)),1000000000000),IF((INDEX(T1_Rente,2)-0.005+0.000005)>Berekening!D10,(Berekening!D45-(INDEX(T1_Rente,2)-0.005+0.000005)*Berekening!D46)/(360*((INDEX(T1_Rente,2)-0.005+0.000005)-Berekening!D10)),1000000000000)) -> -280717.48 | E16: =MIN(1000000000000,IF((INDEX(T1_Rente,2)+0.000005)<Berekening!E10,(Berekening!E45-(INDEX(T1_Rente,2)+0.000005)*Berekening!E46)/(360*((INDEX(T1_Rente,2)+0.000005)-Berekening!E10)),1000000000000),IF((INDEX(T1_Rente,2)-0.005+0.000005)>Berekening!E10,(Berekening!E45-(INDEX(T1_Rente,2)-0.005+0.000005)*Berekening!E46)/(360*((INDEX(T1_Rente,2)-0.005+0.000005)-Berekening!E10)),1000000000000)) -> -638876.23 | F16: =MIN(1000000000000,IF((INDEX(T1_Rente,2)+0.000005)<Berekening!F10,(Berekening!F45-(INDEX(T1_Rente,2)+0.000005)*Berekening!F46)/(360*((INDEX(T1_Rente,2)+0.000005)-Berekening!F10)),1000000000000),IF((INDEX(T1_Rente,2)-0.005+0.000005)>Berekening!F10,(Berekening!F45-(INDEX(T1_Rente,2)-0.005+0.000005)*Berekening!F46)/(360*((INDEX(T1_Rente,2)-0.005+0.000005)-Berekening!F10)),1000000000000)) -> -200803.27 | G16: =MIN(1000000000000,IF((INDEX(T1_Rente,2)+0.000005)<Berekening!G10,(Berekening!G45-(INDEX(T1_Rente,2)+0.000005)*Berekening!G46)/(360*((INDEX(T1_Rente,2)+0.000005)-Berekening!G10)),1000000000000),IF((INDEX(T1_Rente,2)-0.005+0.000005)>Berekening!G10,(Berekening!G45-(INDEX(T1_Rente,2)-0.005+0.000005)*Berekening!G46)/(360*((INDEX(T1_Rente,2)-0.005+0.000005)-Berekening!G10)),1000000000000)) -> 0 | H16: =MIN(1000000000000,IF((INDEX(T1_Rente,2)+0.000005)<Berekening!H10,(Berekening!H45-(INDEX(T1_Rente,2)+0.000005)*Berekening!H46)/(360*((INDEX(T1_Rente,2)+0.000005)-Berekening!H10)),1000000000000),IF((INDEX(T1_Rente,2)-0.005+0.000005)>Berekening!H10,(Berekening!H45-(INDEX(T1_Rente,2)-0.005+0.000005)*Berekening!H46)/(360*((INDEX(T1_Rente,2)-0.005+0.000005)-Berekening!H10)),1000000000000)) -> 0 | I16: =MIN(1000000000000,IF((INDEX(T1_Rente,2)+0.000005)<Berekening!I10,(Berekening!I45-(INDEX(T1_Rente,2)+0.000005)*Berekening!I46)/(360*((INDEX(T1_Rente,2)+0.000005)-Berekening!I10)),1000000000000),IF((INDEX(T1_Rente,2)-0.005+0.000005)>Berekening!I10,(Berekening!I45-(INDEX(T1_Rente,2)-0.005+0.000005)*Berekening!I46)/(360*((INDEX(T1_Rente,2)-0.005+0.000005)-Berekening!I10)),1000000000000)) -> 0 | J16: =MIN(1000000000000,IF((INDEX(T1_Rente,2)+0.000005)<Berekening!J10,(Berekening!J45-(INDEX(T1_Rente,2)+0.000005)*Berekening!J46)/(360*((INDEX(T1_Rente,2)+0.000005)-Berekening!J10)),1000000000000),IF((INDEX(T1_Rente,2)-0.005+0.000005)>Berekening!J10,(Berekening!J45-(INDEX(T1_Rente,2)-0.005+0.000005)*Berekening!J46)/(360*((INDEX(T1_Rente,2)-0.005+0.000005)-Berekening!J10)),1000000000000)) -> -223948.47 | ... M16: =MIN(1000000000000,IF((INDEX(T1_Rente,2)+0.000005)<Berekening!M10,(Berekening!M45-(INDEX(T1_Rente,2)+0.000005)*Berekening!M46)/(360*((INDEX(T1_Rente,2)+0.000005)-Berekening!M10)),1000000000000),IF((INDEX(T1_Rente,2)-0.005+0.000005)>Berekening!M10,(Berekening!M45-(INDEX(T1_Rente,2)-0.005+0.000005)*Berekening!M46)/(360*((INDEX(T1_Rente,2)-0.005+0.000005)-Berekening!M10)),1000000000000)) -> -223948.47
A17: Kolom 2: haalbaar bedrag (−1 = onmogelijk) | B17: € | C17: =IF(C15>C16,-1,IF(C14<C15-0.000000001,-1,IF(C14>C16,MAX(C15,C16-1),C14))) -> -1 | D17: =IF(D15>D16,-1,IF(D14<D15-0.000000001,-1,IF(D14>D16,MAX(D15,D16-1),D14))) -> -1 | E17: =IF(E15>E16,-1,IF(E14<E15-0.000000001,-1,IF(E14>E16,MAX(E15,E16-1),E14))) -> -1 | F17: =IF(F15>F16,-1,IF(F14<F15-0.000000001,-1,IF(F14>F16,MAX(F15,F16-1),F14))) -> -1 | G17: =IF(G15>G16,-1,IF(G14<G15-0.000000001,-1,IF(G14>G16,MAX(G15,G16-1),G14))) -> 0 | H17: =IF(H15>H16,-1,IF(H14<H15-0.000000001,-1,IF(H14>H16,MAX(H15,H16-1),H14))) -> 0 | I17: =IF(I15>I16,-1,IF(I14<I15-0.000000001,-1,IF(I14>I16,MAX(I15,I16-1),I14))) -> 0 | J17: =IF(J15>J16,-1,IF(J14<J15-0.000000001,-1,IF(J14>J16,MAX(J15,J16-1),J14))) -> -1 | ... M17: =IF(M15>M16,-1,IF(M14<M15-0.000000001,-1,IF(M14>M16,MAX(M15,M16-1),M14))) -> -1
A18: Kolom 3: woonquote | B18: % | C18: =INDEX(T1_Tabel,Berekening!C80,3)+(Berekening!C79-INDEX(T1_Inkomen,Berekening!C80))/(INDEX(T1_Inkomen,Berekening!C80+1)-INDEX(T1_Inkomen,Berekening!C80))*(INDEX(T1_Tabel,Berekening!C80+1,3)-INDEX(T1_Tabel,Berekening!C80,3)) -> 0.244 | D18: =INDEX(T1_Tabel,Berekening!D80,3)+(Berekening!D79-INDEX(T1_Inkomen,Berekening!D80))/(INDEX(T1_Inkomen,Berekening!D80+1)-INDEX(T1_Inkomen,Berekening!D80))*(INDEX(T1_Tabel,Berekening!D80+1,3)-INDEX(T1_Tabel,Berekening!D80,3)) -> 0.244 | E18: =INDEX(T1_Tabel,Berekening!E80,3)+(Berekening!E79-INDEX(T1_Inkomen,Berekening!E80))/(INDEX(T1_Inkomen,Berekening!E80+1)-INDEX(T1_Inkomen,Berekening!E80))*(INDEX(T1_Tabel,Berekening!E80+1,3)-INDEX(T1_Tabel,Berekening!E80,3)) -> 0.244 | F18: =INDEX(T1_Tabel,Berekening!F80,3)+(Berekening!F79-INDEX(T1_Inkomen,Berekening!F80))/(INDEX(T1_Inkomen,Berekening!F80+1)-INDEX(T1_Inkomen,Berekening!F80))*(INDEX(T1_Tabel,Berekening!F80+1,3)-INDEX(T1_Tabel,Berekening!F80,3)) -> 0.244 | G18: =INDEX(T1_Tabel,Berekening!G80,3)+(Berekening!G79-INDEX(T1_Inkomen,Berekening!G80))/(INDEX(T1_Inkomen,Berekening!G80+1)-INDEX(T1_Inkomen,Berekening!G80))*(INDEX(T1_Tabel,Berekening!G80+1,3)-INDEX(T1_Tabel,Berekening!G80,3)) -> 0.197 | H18: =INDEX(T1_Tabel,Berekening!H80,3)+(Berekening!H79-INDEX(T1_Inkomen,Berekening!H80))/(INDEX(T1_Inkomen,Berekening!H80+1)-INDEX(T1_Inkomen,Berekening!H80))*(INDEX(T1_Tabel,Berekening!H80+1,3)-INDEX(T1_Tabel,Berekening!H80,3)) -> 0.244 | I18: =INDEX(T1_Tabel,Berekening!I80,3)+(Berekening!I79-INDEX(T1_Inkomen,Berekening!I80))/(INDEX(T1_Inkomen,Berekening!I80+1)-INDEX(T1_Inkomen,Berekening!I80))*(INDEX(T1_Tabel,Berekening!I80+1,3)-INDEX(T1_Tabel,Berekening!I80,3)) -> 0.244 | J18: =INDEX(T1_Tabel,Berekening!J80,3)+(Berekening!J79-INDEX(T1_Inkomen,Berekening!J80))/(INDEX(T1_Inkomen,Berekening!J80+1)-INDEX(T1_Inkomen,Berekening!J80))*(INDEX(T1_Tabel,Berekening!J80+1,3)-INDEX(T1_Tabel,Berekening!J80,3)) -> 0.244 | ... M18: =INDEX(T1_Tabel,Berekening!M80,3)+(Berekening!M79-INDEX(T1_Inkomen,Berekening!M80))/(INDEX(T1_Inkomen,Berekening!M80+1)-INDEX(T1_Inkomen,Berekening!M80))*(INDEX(T1_Tabel,Berekening!M80+1,3)-INDEX(T1_Tabel,Berekening!M80,3)) -> 0.244
A19: Kolom 3: bedrag als de woonquote van deze kolom geldt | B19: € | C19: =MAX(0,(C18*C6/12-Berekening!C18-Berekening!C44)*Berekening!C11-Berekening!C75+C7) -> 219769.18 | D19: =MAX(0,(D18*D6/12-Berekening!D18-Berekening!D44)*Berekening!D11-Berekening!D75+D7) -> 248820.73 | E19: =MAX(0,(E18*E6/12-Berekening!E18-Berekening!E44)*Berekening!E11-Berekening!E75+E7) -> 97121.634 | F19: =MAX(0,(F18*F6/12-Berekening!F18-Berekening!F44)*Berekening!F11-Berekening!F75+F7) -> 212428.84 | G19: =MAX(0,(G18*G6/12-Berekening!G18-Berekening!G44)*Berekening!G11-Berekening!G75+G7) -> 212140.89 | H19: =MAX(0,(H18*H6/12-Berekening!H18-Berekening!H44)*Berekening!H11-Berekening!H75+H7) -> 568647.44 | I19: =MAX(0,(I18*I6/12-Berekening!I18-Berekening!I44)*Berekening!I11-Berekening!I75+I7) -> 772541.08 | J19: =MAX(0,(J18*J6/12-Berekening!J18-Berekening!J44)*Berekening!J11-Berekening!J75+J7) -> 257055.25 | ... M19: =MAX(0,(M18*M6/12-Berekening!M18-Berekening!M44)*Berekening!M11-Berekening!M75+M7) -> 219769.18
